<sdf version='1.6'>
  <model name='gripper'>
    <link name='gripper_wide_block_p'>
      <pose frame=''>0 0 0 0 -0 0</pose>
      <inertial>
        <pose frame=''>0.036207 0 0 0 -0 0</pose>
        <mass>0.783</mass>
        <inertia>
          <ixx>0.0111512</ixx>
          <ixy>0</ixy>
          <ixz>0</ixz>
          <iyy>0.00188368</iyy>
          <iyz>0</iyz>
          <izz>0.0127087</izz>
        </inertia>
      </inertial>
      <collision name='gripper_wide_block_p_fixed_joint_lump__collision_collision'>
        <pose frame=''>0 0 0 0 -0 0</pose>
        <geometry>
          <box>
            <size>0.01 0.3 0.05</size>
          </box>
        </geometry>
      </collision>
      <collision name='gripper_wide_block_p_fixed_joint_lump__collision_collision_1'>
        <pose frame=''>0.075 0.145 0 0 -0 0</pose>
        <geometry>
          <box>
            <size>0.14 0.01 0.05</size>
          </box>
        </geometry>
      </collision>
      <collision name='gripper_wide_block_p_fixed_joint_lump__collision_collision_2'>
        <pose frame=''>0.075 -0.145 0 0 -0 0</pose>
        <geometry>
          <box>
            <size>0.14 0.01 0.05</size>
          </box>
        </geometry>
      </collision>
      <visual name='gripper_wide_block_p_visual'>
        <pose frame=''>0 0 0 0 -0 0</pose>
        <geometry>
          <box>
            <size>0.01 0.3 0.05</size>
          </box>
        </geometry>
      </visual>
      <visual name='gripper_wide_block_p_fixed_joint_lump__gripper_side_block_p1_visual_1'>
        <pose frame=''>0.075 0.145 0 0 -0 0</pose>
        <geometry>
          <box>
            <size>0.14 0.01 0.05</size>
          </box>
        </geometry>
      </visual>
      <visual name='gripper_wide_block_p_fixed_joint_lump__gripper_side_block_p2_visual_2'>
        <pose frame=''>0.075 -0.145 0 0 -0 0</pose>
        <geometry>
          <box>
            <size>0.14 0.01 0.05</size>
          </box>
        </geometry>
      </visual>
    </link>
    <link name='gripper_wide_block_d'>
      <pose frame=''>0.304 0 0 0 -0 0</pose>
      <inertial>
        <pose frame=''>-0.036207 0 0 0 -0 0</pose>
        <mass>0.783</mass>
        <inertia>
          <ixx>0.0111512</ixx>
          <ixy>0</ixy>
          <ixz>0</ixz>
          <iyy>0.00188368</iyy>
          <iyz>0</iyz>
          <izz>0.0127087</izz>
        </inertia>
      </inertial>
      <collision name='gripper_wide_block_d_fixed_joint_lump__collision_collision'>
        <pose frame=''>0 0 0 0 -0 0</pose>
        <geometry>
          <box>
            <size>0.01 0.3 0.05</size>
          </box>
        </geometry>
      </collision>
      <collision name='gripper_wide_block_d_fixed_joint_lump__collision_collision_1'>
        <pose frame=''>-0.075 0.145 0 0 -0 0</pose>
        <geometry>
          <box>
            <size>0.14 0.01 0.05</size>
          </box>
        </geometry>
      </collision>
      <collision name='gripper_wide_block_d_fixed_joint_lump__collision_collision_2'>
        <pose frame=''>-0.075 -0.145 0 0 -0 0</pose>
        <geometry>
          <box>
            <size>0.14 0.01 0.05</size>
          </box>
        </geometry>
      </collision>
      <visual name='gripper_wide_block_d_visual'>
        <pose frame=''>0 0 0 0 -0 0</pose>
        <geometry>
          <box>
            <size>0.01 0.3 0.05</size>
          </box>
        </geometry>
      </visual>
      <visual name='gripper_wide_block_d_fixed_joint_lump__gripper_side_block_d1_visual_1'>
        <pose frame=''>-0.075 0.145 0 0 -0 0</pose>
        <geometry>
          <box>
            <size>0.14 0.01 0.05</size>
          </box>
        </geometry>
      </visual>
      <visual name='gripper_wide_block_d_fixed_joint_lump__gripper_side_block_d2_visual_2'>
        <pose frame=''>-0.075 -0.145 0 0 -0 0</pose>
        <geometry>
          <box>
            <size>0.14 0.01 0.05</size>
          </box>
        </geometry>
      </visual>
    </link>
    <joint name='gripper_joint' type='revolute'>
      <child>gripper_wide_block_d</child>
      <parent>gripper_wide_block_p</parent>
      <axis>
        <xyz>1 0 0</xyz>
        <limit>
          <lower>-1e+16</lower>
          <upper>1e+16</upper>
        </limit>
        <dynamics>
          <spring_reference>0</spring_reference>
          <spring_stiffness>0</spring_stiffness>
        </dynamics>
        <use_parent_model_frame>1</use_parent_model_frame>
      </axis>
    </joint>
    <static>0</static>
    <plugin name='gazebo_ros_control' filename='libgazebo_ros_control.so'>
      <robotNamespace>/gripper</robotNamespace>
    </plugin>
  </model>
</sdf>
