<?xml version="1.0" ?>
<!-- =================================================================================== -->
<!-- |    This document was autogenerated by xacro from gripper_01.urdf.xacro          | -->
<!-- |    EDITING THIS FILE BY HAND IS NOT RECOMMENDED                                 | -->
<!-- =================================================================================== -->
<robot name="gripper" xmlns:xacro="http://ros.org/wiki/xacro">
  <link name="gripper_wide_block_p">
    <visual>
      <geometry>
        <box size="0.01 0.3 0.05"/>
      </geometry>
    </visual>
    <collision name="collision">
      <geometry>
        <box size="0.01 0.3 0.05"/>
      </geometry>
    </collision>
    <inertial>
      <mass value="0.405"/>
      <inertia ixx="0.003121875" ixy="0.0" ixz="0.0" iyy="8.775e-05" iyz="0.0" izz="0.003040875"/>
    </inertial>
  </link>
  <link name="gripper_side_block_p1">
    <visual>
      <geometry>
        <box size="0.14 0.01 0.05"/>
      </geometry>
    </visual>
    <collision name="collision">
      <geometry>
        <box size="0.14 0.01 0.05"/>
      </geometry>
    </collision>
    <inertial>
      <mass value="0.189"/>
      <inertia ixx="4.095e-05" ixy="0.0" ixz="0.0" iyy="0.000348075" iyz="0.0" izz="0.000310275"/>
    </inertial>
  </link>
  <link name="gripper_side_block_p2">
    <visual>
      <geometry>
        <box size="0.14 0.01 0.05"/>
      </geometry>
    </visual>
    <collision name="collision">
      <geometry>
        <box size="0.14 0.01 0.05"/>
      </geometry>
    </collision>
    <inertial>
      <mass value="0.189"/>
      <inertia ixx="4.095e-05" ixy="0.0" ixz="0.0" iyy="0.000348075" iyz="0.0" izz="0.000310275"/>
    </inertial>
  </link>
  <link name="gripper_wide_block_d">
    <visual>
      <geometry>
        <box size="0.01 0.3 0.05"/>
      </geometry>
    </visual>
    <collision name="collision">
      <geometry>
        <box size="0.01 0.3 0.05"/>
      </geometry>
    </collision>
    <inertial>
      <mass value="0.405"/>
      <inertia ixx="0.003121875" ixy="0.0" ixz="0.0" iyy="8.775e-05" iyz="0.0" izz="0.003040875"/>
    </inertial>
  </link>
  <link name="gripper_side_block_d1">
    <visual>
      <geometry>
        <box size="0.14 0.01 0.05"/>
      </geometry>
    </visual>
    <collision name="collision">
      <geometry>
        <box size="0.14 0.01 0.05"/>
      </geometry>
    </collision>
    <inertial>
      <mass value="0.189"/>
      <inertia ixx="4.095e-05" ixy="0.0" ixz="0.0" iyy="0.000348075" iyz="0.0" izz="0.000310275"/>
    </inertial>
  </link>
  <link name="gripper_side_block_d2">
    <visual>
      <geometry>
        <box size="0.14 0.01 0.05"/>
      </geometry>
    </visual>
    <collision name="collision">
      <geometry>
        <box size="0.14 0.01 0.05"/>
      </geometry>
    </collision>
    <inertial>
      <mass value="0.189"/>
      <inertia ixx="4.095e-05" ixy="0.0" ixz="0.0" iyy="0.000348075" iyz="0.0" izz="0.000310275"/>
    </inertial>
  </link>
  <joint name="block_fixed_joint_p1" type="fixed">
    <origin rpy="0 0 0" xyz="0.075 0.145 0"/>
    <parent link="gripper_wide_block_p"/>
    <child link="gripper_side_block_p1"/>
  </joint>
  <joint name="block_fixed_joint_p2" type="fixed">
    <origin rpy="0 0 0" xyz="0.075 -0.145 0"/>
    <parent link="gripper_wide_block_p"/>
    <child link="gripper_side_block_p2"/>
  </joint>
  <joint name="block_fixed_joint_d1" type="fixed">
    <origin rpy="0 0 0" xyz="-0.075 0.145 0"/>
    <parent link="gripper_wide_block_d"/>
    <child link="gripper_side_block_d1"/>
  </joint>
  <joint name="block_fixed_joint_d2" type="fixed">
    <origin rpy="0 0 0" xyz="-0.075 -0.145 0"/>
    <parent link="gripper_wide_block_d"/>
    <child link="gripper_side_block_d2"/>
  </joint>
  <!-- Prismatic joint -->
  <joint name="gripper_joint" type="continuous">
    <origin rpy="0 0 0" xyz="0.304 0 0"/>
    <parent link="gripper_wide_block_p"/>
    <child link="gripper_wide_block_d"/>
  </joint>
  <transmission name="gripper_joint_transmission">
    <type>transmission_interface/SimpleTransmission</type>
    <joint name="gripper_joint">
      <hardwareInterface>EffortJointInterface</hardwareInterface>
    </joint>
    <actuator name="motor1">
      <hardwareInterface>EffortJointInterface</hardwareInterface>
      <mechanicalReduction>1</mechanicalReduction>
    </actuator>
  </transmission>
  <gazebo>
    <plugin filename="libgazebo_ros_control.so" name="gazebo_ros_control">
      <robotNamespace>/gripper</robotNamespace>
    </plugin>
  </gazebo>
</robot>

