<?xml version="1.0" ?>
<!-- =================================================================================== -->
<!-- |    This document was autogenerated by xacro from mobile_arm.urdf.xacro          | -->
<!-- |    EDITING THIS FILE BY HAND IS NOT RECOMMENDED                                 | -->
<!-- =================================================================================== -->
<robot name="mobile_ur10" xmlns:xacro="http://ros.org/wiki/xacro">
  <gazebo>
    <!-- turn on self-collision detection so that links will not pass through each other -->
    <self_collide>0</self_collide>
    <!-- for the UR10, copied from $(find ur_description)/urdf/common.gazebo.xacro -->
    <plugin filename="libgazebo_ros_control.so" name="ros_control"/>
  </gazebo>
  <!-- Chassis link -->
  <link name="chassis">
    <visual name="visual">
      <geometry>
        <box size="0.89 0.58 0.2"/>
      </geometry>
    </visual>
    <collision name="collision">
      <geometry>
        <box size="0.89 0.58 0.2"/>
      </geometry>
    </collision>
    <inertial>
      <mass value="63.65"/>
      <inertia ixx="1.99648833333" ixy="0.0" ixz="0.0" iyy="4.41359708333" iyz="0.0" izz="5.98575208333"/>
    </inertial>
  </link>
  <link name="wheel_1_link">
    <!-- Note: must omit name="foo" because in Gazebo 7 the urdf parser has a bug that would make <gazebo reference="bar"> not work -->
    <visual>
      <geometry>
        <cylinder length="0.02" radius="0.071"/>
      </geometry>
      <material name="red">
        <color rgba="1 0 0 1"/>
      </material>
    </visual>
    <!-- Note: must omit name="foo" because in Gazebo 7 the urdf parser has a bug that would make <gazebo reference="bar"> not work -->
    <collision>
      <geometry>
        <cylinder length="0.02" radius="0.071"/>
      </geometry>
    </collision>
    <inertial>
      <mass value="0.558333333333"/>
      <inertia ixx="0.000722250694444" ixy="0.0" ixz="0.0" iyy="0.000722250694444" iyz="0.0" izz="0.00140727916667"/>
    </inertial>
  </link>
  <joint name="wheel_1_joint" type="fixed">
    <axis xyz="0 0 1"/>
    <parent link="chassis"/>
    <child link="wheel_1_link"/>
    <origin rpy="-1.5707963268 0 0" xyz="0.374 0.28 -0.181"/>
  </joint>
  <link name="wheel_2_link">
    <!-- Note: must omit name="foo" because in Gazebo 7 the urdf parser has a bug that would make <gazebo reference="bar"> not work -->
    <visual>
      <geometry>
        <cylinder length="0.02" radius="0.071"/>
      </geometry>
      <material name="red">
        <color rgba="1 0 0 1"/>
      </material>
    </visual>
    <!-- Note: must omit name="foo" because in Gazebo 7 the urdf parser has a bug that would make <gazebo reference="bar"> not work -->
    <collision>
      <geometry>
        <cylinder length="0.02" radius="0.071"/>
      </geometry>
    </collision>
    <inertial>
      <mass value="0.558333333333"/>
      <inertia ixx="0.000722250694444" ixy="0.0" ixz="0.0" iyy="0.000722250694444" iyz="0.0" izz="0.00140727916667"/>
    </inertial>
  </link>
  <joint name="wheel_2_joint" type="continuous">
    <axis xyz="0 0 1"/>
    <parent link="chassis"/>
    <child link="wheel_2_link"/>
    <origin rpy="-1.5707963268 0 0" xyz="0 0.28 -0.181"/>
  </joint>
  <link name="wheel_3_link">
    <!-- Note: must omit name="foo" because in Gazebo 7 the urdf parser has a bug that would make <gazebo reference="bar"> not work -->
    <visual>
      <geometry>
        <cylinder length="0.02" radius="0.071"/>
      </geometry>
      <material name="red">
        <color rgba="1 0 0 1"/>
      </material>
    </visual>
    <!-- Note: must omit name="foo" because in Gazebo 7 the urdf parser has a bug that would make <gazebo reference="bar"> not work -->
    <collision>
      <geometry>
        <cylinder length="0.02" radius="0.071"/>
      </geometry>
    </collision>
    <inertial>
      <mass value="0.558333333333"/>
      <inertia ixx="0.000722250694444" ixy="0.0" ixz="0.0" iyy="0.000722250694444" iyz="0.0" izz="0.00140727916667"/>
    </inertial>
  </link>
  <joint name="wheel_3_joint" type="fixed">
    <axis xyz="0 0 1"/>
    <parent link="chassis"/>
    <child link="wheel_3_link"/>
    <origin rpy="-1.5707963268 0 0" xyz="-0.374 0.28 -0.181"/>
  </joint>
  <link name="wheel_4_link">
    <!-- Note: must omit name="foo" because in Gazebo 7 the urdf parser has a bug that would make <gazebo reference="bar"> not work -->
    <visual>
      <geometry>
        <cylinder length="0.02" radius="0.071"/>
      </geometry>
      <material name="red">
        <color rgba="1 0 0 1"/>
      </material>
    </visual>
    <!-- Note: must omit name="foo" because in Gazebo 7 the urdf parser has a bug that would make <gazebo reference="bar"> not work -->
    <collision>
      <geometry>
        <cylinder length="0.02" radius="0.071"/>
      </geometry>
    </collision>
    <inertial>
      <mass value="0.558333333333"/>
      <inertia ixx="0.000722250694444" ixy="0.0" ixz="0.0" iyy="0.000722250694444" iyz="0.0" izz="0.00140727916667"/>
    </inertial>
  </link>
  <joint name="wheel_4_joint" type="fixed">
    <axis xyz="0 0 1"/>
    <parent link="chassis"/>
    <child link="wheel_4_link"/>
    <origin rpy="-1.5707963268 0 0" xyz="-0.374 -0.28 -0.181"/>
  </joint>
  <link name="wheel_5_link">
    <!-- Note: must omit name="foo" because in Gazebo 7 the urdf parser has a bug that would make <gazebo reference="bar"> not work -->
    <visual>
      <geometry>
        <cylinder length="0.02" radius="0.071"/>
      </geometry>
      <material name="red">
        <color rgba="1 0 0 1"/>
      </material>
    </visual>
    <!-- Note: must omit name="foo" because in Gazebo 7 the urdf parser has a bug that would make <gazebo reference="bar"> not work -->
    <collision>
      <geometry>
        <cylinder length="0.02" radius="0.071"/>
      </geometry>
    </collision>
    <inertial>
      <mass value="0.558333333333"/>
      <inertia ixx="0.000722250694444" ixy="0.0" ixz="0.0" iyy="0.000722250694444" iyz="0.0" izz="0.00140727916667"/>
    </inertial>
  </link>
  <joint name="wheel_5_joint" type="continuous">
    <axis xyz="0 0 1"/>
    <parent link="chassis"/>
    <child link="wheel_5_link"/>
    <origin rpy="-1.5707963268 0 0" xyz="0 -0.28 -0.181"/>
  </joint>
  <link name="wheel_6_link">
    <!-- Note: must omit name="foo" because in Gazebo 7 the urdf parser has a bug that would make <gazebo reference="bar"> not work -->
    <visual>
      <geometry>
        <cylinder length="0.02" radius="0.071"/>
      </geometry>
      <material name="red">
        <color rgba="1 0 0 1"/>
      </material>
    </visual>
    <!-- Note: must omit name="foo" because in Gazebo 7 the urdf parser has a bug that would make <gazebo reference="bar"> not work -->
    <collision>
      <geometry>
        <cylinder length="0.02" radius="0.071"/>
      </geometry>
    </collision>
    <inertial>
      <mass value="0.558333333333"/>
      <inertia ixx="0.000722250694444" ixy="0.0" ixz="0.0" iyy="0.000722250694444" iyz="0.0" izz="0.00140727916667"/>
    </inertial>
  </link>
  <joint name="wheel_6_joint" type="fixed">
    <axis xyz="0 0 1"/>
    <parent link="chassis"/>
    <child link="wheel_6_link"/>
    <origin rpy="-1.5707963268 0 0" xyz="0.374 -0.28 -0.181"/>
  </joint>
  <gazebo reference="wheel_1_link">
    <mu1>0</mu1>
    <mu2>0</mu2>
    <material>Gazebo/Red</material>
  </gazebo>
  <gazebo reference="wheel_3_link">
    <mu1>0</mu1>
    <mu2>0</mu2>
    <material>Gazebo/Red</material>
  </gazebo>
  <gazebo reference="wheel_4_link">
    <mu1>0</mu1>
    <mu2>0</mu2>
    <material>Gazebo/Red</material>
  </gazebo>
  <gazebo reference="wheel_6_link">
    <mu1>0</mu1>
    <mu2>0</mu2>
    <material>Gazebo/Red</material>
  </gazebo>
  <!-- MQMX to (possibly?) replace this with ros control plugin -->
  <plugin filename="libgazebo_ros_diff_drive.so" name="differential_drive_controller">
    <leftJoint>wheel_2_joint</leftJoint>
    <rightJoint>wheel_5_joint</rightJoint>
    <robotBaseFrame>chassis</robotBaseFrame>
    <wheelSeparation>0.56</wheelSeparation>
    <wheelDiameter>0.142</wheelDiameter>
    <publishWheelJointState>true</publishWheelJointState>
    <legacyMode>false</legacyMode>
  </plugin>
  <!--
  Author: Kelsey Hawkins
  Contributers: Jimmy Da Silva, Ajit Krisshna N L, Muhammad Asif Rana
-->
  <!-- measured from model -->
  <link name="base_link">
    <visual>
      <geometry>
        <mesh filename="package://ur_description/meshes/ur10/visual/base.dae"/>
      </geometry>
      <material name="LightGrey">
        <color rgba="0.7 0.7 0.7 1.0"/>
      </material>
    </visual>
    <collision>
      <geometry>
        <mesh filename="package://ur_description/meshes/ur10/collision/base.stl"/>
      </geometry>
    </collision>
    <inertial>
      <mass value="4.0"/>
      <origin rpy="0 0 0" xyz="0.0 0.0 0.0"/>
      <inertia ixx="0.0061063308908" ixy="0.0" ixz="0.0" iyy="0.0061063308908" iyz="0.0" izz="0.01125"/>
    </inertial>
  </link>
  <joint name="shoulder_pan_joint" type="revolute">
    <parent link="base_link"/>
    <child link="shoulder_link"/>
    <origin rpy="0.0 0.0 0.0" xyz="0.0 0.0 0.1273"/>
    <axis xyz="0 0 1"/>
    <limit effort="330.0" lower="-3.14159265359" upper="3.14159265359" velocity="2.16"/>
    <dynamics damping="0.0" friction="0.0"/>
  </joint>
  <link name="shoulder_link">
    <visual>
      <geometry>
        <mesh filename="package://ur_description/meshes/ur10/visual/shoulder.dae"/>
      </geometry>
      <material name="LightGrey">
        <color rgba="0.7 0.7 0.7 1.0"/>
      </material>
    </visual>
    <collision>
      <geometry>
        <mesh filename="package://ur_description/meshes/ur10/collision/shoulder.stl"/>
      </geometry>
    </collision>
    <inertial>
      <mass value="7.778"/>
      <origin rpy="0 0 0" xyz="0.0 0.0 0.0"/>
      <inertia ixx="0.0314743125769" ixy="0.0" ixz="0.0" iyy="0.0314743125769" iyz="0.0" izz="0.021875625"/>
    </inertial>
  </link>
  <joint name="shoulder_lift_joint" type="revolute">
    <parent link="shoulder_link"/>
    <child link="upper_arm_link"/>
    <origin rpy="0.0 1.5707963268 0.0" xyz="0.0 0.220941 0.0"/>
    <axis xyz="0 1 0"/>
    <limit effort="330.0" lower="-3.14159265359" upper="3.14159265359" velocity="2.16"/>
    <dynamics damping="0.0" friction="0.0"/>
  </joint>
  <link name="upper_arm_link">
    <visual>
      <geometry>
        <mesh filename="package://ur_description/meshes/ur10/visual/upperarm.dae"/>
      </geometry>
      <material name="LightGrey">
        <color rgba="0.7 0.7 0.7 1.0"/>
      </material>
    </visual>
    <collision>
      <geometry>
        <mesh filename="package://ur_description/meshes/ur10/collision/upperarm.stl"/>
      </geometry>
    </collision>
    <inertial>
      <mass value="12.93"/>
      <origin rpy="0 0 0" xyz="0.0 0.0 0.306"/>
      <inertia ixx="0.421753803798" ixy="0.0" ixz="0.0" iyy="0.421753803798" iyz="0.0" izz="0.036365625"/>
    </inertial>
  </link>
  <joint name="elbow_joint" type="revolute">
    <parent link="upper_arm_link"/>
    <child link="forearm_link"/>
    <origin rpy="0.0 0.0 0.0" xyz="0.0 -0.1719 0.612"/>
    <axis xyz="0 1 0"/>
    <limit effort="150.0" lower="-3.14159265359" upper="3.14159265359" velocity="3.15"/>
    <dynamics damping="0.0" friction="0.0"/>
  </joint>
  <link name="forearm_link">
    <visual>
      <geometry>
        <mesh filename="package://ur_description/meshes/ur10/visual/forearm.dae"/>
      </geometry>
      <material name="LightGrey">
        <color rgba="0.7 0.7 0.7 1.0"/>
      </material>
    </visual>
    <collision>
      <geometry>
        <mesh filename="package://ur_description/meshes/ur10/collision/forearm.stl"/>
      </geometry>
    </collision>
    <inertial>
      <mass value="3.87"/>
      <origin rpy="0 0 0" xyz="0.0 0.0 0.28615"/>
      <inertia ixx="0.111069694097" ixy="0.0" ixz="0.0" iyy="0.111069694097" iyz="0.0" izz="0.010884375"/>
    </inertial>
  </link>
  <joint name="wrist_1_joint" type="revolute">
    <parent link="forearm_link"/>
    <child link="wrist_1_link"/>
    <origin rpy="0.0 1.5707963268 0.0" xyz="0.0 0.0 0.5723"/>
    <axis xyz="0 1 0"/>
    <limit effort="54.0" lower="-3.14159265359" upper="3.14159265359" velocity="3.2"/>
    <dynamics damping="0.0" friction="0.0"/>
  </joint>
  <link name="wrist_1_link">
    <visual>
      <geometry>
        <mesh filename="package://ur_description/meshes/ur10/visual/wrist1.dae"/>
      </geometry>
      <material name="LightGrey">
        <color rgba="0.7 0.7 0.7 1.0"/>
      </material>
    </visual>
    <collision>
      <geometry>
        <mesh filename="package://ur_description/meshes/ur10/collision/wrist1.stl"/>
      </geometry>
    </collision>
    <inertial>
      <mass value="1.96"/>
      <origin rpy="0 0 0" xyz="0.0 0.0 0.0"/>
      <inertia ixx="0.0051082479567" ixy="0.0" ixz="0.0" iyy="0.0051082479567" iyz="0.0" izz="0.0055125"/>
    </inertial>
  </link>
  <joint name="wrist_2_joint" type="revolute">
    <parent link="wrist_1_link"/>
    <child link="wrist_2_link"/>
    <origin rpy="0.0 0.0 0.0" xyz="0.0 0.1149 0.0"/>
    <axis xyz="0 0 1"/>
    <limit effort="54.0" lower="-3.14159265359" upper="3.14159265359" velocity="3.2"/>
    <dynamics damping="0.0" friction="0.0"/>
  </joint>
  <link name="wrist_2_link">
    <visual>
      <geometry>
        <mesh filename="package://ur_description/meshes/ur10/visual/wrist2.dae"/>
      </geometry>
      <material name="LightGrey">
        <color rgba="0.7 0.7 0.7 1.0"/>
      </material>
    </visual>
    <collision>
      <geometry>
        <mesh filename="package://ur_description/meshes/ur10/collision/wrist2.stl"/>
      </geometry>
    </collision>
    <inertial>
      <mass value="1.96"/>
      <origin rpy="0 0 0" xyz="0.0 0.0 0.0"/>
      <inertia ixx="0.0051082479567" ixy="0.0" ixz="0.0" iyy="0.0051082479567" iyz="0.0" izz="0.0055125"/>
    </inertial>
  </link>
  <joint name="wrist_3_joint" type="revolute">
    <parent link="wrist_2_link"/>
    <child link="wrist_3_link"/>
    <origin rpy="0.0 0.0 0.0" xyz="0.0 0.0 0.1157"/>
    <axis xyz="0 1 0"/>
    <limit effort="54.0" lower="-3.14159265359" upper="3.14159265359" velocity="3.2"/>
    <dynamics damping="0.0" friction="0.0"/>
  </joint>
  <link name="wrist_3_link">
    <visual>
      <geometry>
        <mesh filename="package://ur_description/meshes/ur10/visual/wrist3.dae"/>
      </geometry>
      <material name="LightGrey">
        <color rgba="0.7 0.7 0.7 1.0"/>
      </material>
    </visual>
    <collision>
      <geometry>
        <mesh filename="package://ur_description/meshes/ur10/collision/wrist3.stl"/>
      </geometry>
    </collision>
    <inertial>
      <mass value="0.202"/>
      <origin rpy="0 0 0" xyz="0.0 0.0 0.0"/>
      <inertia ixx="0.000526462289415" ixy="0.0" ixz="0.0" iyy="0.000526462289415" iyz="0.0" izz="0.000568125"/>
    </inertial>
  </link>
  <joint name="ee_fixed_joint" type="fixed">
    <parent link="wrist_3_link"/>
    <child link="ee_link"/>
    <origin rpy="0.0 0.0 1.5707963268" xyz="0.0 0.0922 0.0"/>
  </joint>
  <link name="ee_link">
    <collision>
      <geometry>
        <box size="0.01 0.01 0.01"/>
      </geometry>
      <origin rpy="0 0 0" xyz="-0.01 0 0"/>
    </collision>
  </link>
  <transmission name="shoulder_pan_trans">
    <type>transmission_interface/SimpleTransmission</type>
    <joint name="shoulder_pan_joint">
      <hardwareInterface>hardware_interface/PositionJointInterface</hardwareInterface>
    </joint>
    <actuator name="shoulder_pan_motor">
      <mechanicalReduction>1</mechanicalReduction>
    </actuator>
  </transmission>
  <transmission name="shoulder_lift_trans">
    <type>transmission_interface/SimpleTransmission</type>
    <joint name="shoulder_lift_joint">
      <hardwareInterface>hardware_interface/PositionJointInterface</hardwareInterface>
    </joint>
    <actuator name="shoulder_lift_motor">
      <mechanicalReduction>1</mechanicalReduction>
    </actuator>
  </transmission>
  <transmission name="elbow_trans">
    <type>transmission_interface/SimpleTransmission</type>
    <joint name="elbow_joint">
      <hardwareInterface>hardware_interface/PositionJointInterface</hardwareInterface>
    </joint>
    <actuator name="elbow_motor">
      <mechanicalReduction>1</mechanicalReduction>
    </actuator>
  </transmission>
  <transmission name="wrist_1_trans">
    <type>transmission_interface/SimpleTransmission</type>
    <joint name="wrist_1_joint">
      <hardwareInterface>hardware_interface/PositionJointInterface</hardwareInterface>
    </joint>
    <actuator name="wrist_1_motor">
      <mechanicalReduction>1</mechanicalReduction>
    </actuator>
  </transmission>
  <transmission name="wrist_2_trans">
    <type>transmission_interface/SimpleTransmission</type>
    <joint name="wrist_2_joint">
      <hardwareInterface>hardware_interface/PositionJointInterface</hardwareInterface>
    </joint>
    <actuator name="wrist_2_motor">
      <mechanicalReduction>1</mechanicalReduction>
    </actuator>
  </transmission>
  <transmission name="wrist_3_trans">
    <type>transmission_interface/SimpleTransmission</type>
    <joint name="wrist_3_joint">
      <hardwareInterface>hardware_interface/PositionJointInterface</hardwareInterface>
    </joint>
    <actuator name="wrist_3_motor">
      <mechanicalReduction>1</mechanicalReduction>
    </actuator>
  </transmission>
  <!-- nothing to do here at the moment -->
  <!-- ROS base_link to UR 'Base' Coordinates transform -->
  <link name="base"/>
  <joint name="base_link-base_fixed_joint" type="fixed">
    <!-- NOTE: this rotation is only needed as long as base_link itself is
                 not corrected wrt the real robot (ie: rotated over 180
                 degrees)
      -->
    <origin rpy="0 0 -3.14159265359" xyz="0 0 0"/>
    <parent link="base_link"/>
    <child link="base"/>
  </joint>
  <!-- Frame coincident with all-zeros TCP on UR controller -->
  <link name="tool0"/>
  <joint name="wrist_3_link-tool0_fixed_joint" type="fixed">
    <origin rpy="-1.5707963268 0 0" xyz="0 0.0922 0"/>
    <parent link="wrist_3_link"/>
    <child link="tool0"/>
  </joint>
  <!-- Mount link -->
  <link name="mount_link">
    <visual name="visual">
      <geometry>
        <box size="0.4 0.05 0.01"/>
      </geometry>
    </visual>
    <collision name="collision">
      <geometry>
        <box size="0.4 0.05 0.01"/>
      </geometry>
    </collision>
    <inertial>
      <mass value="0.15"/>
      <inertia ixx="3.25e-05" ixy="0.0" ixz="0.0" iyy="0.00200125" iyz="0.0" izz="0.00203125"/>
    </inertial>
  </link>
  <!-- Gripper link -->
  <link name="gripper_link">
    <visual>
      <geometry>
        <cylinder length="0.4" radius="0.15"/>
      </geometry>
      <material name="white">
        <color rgba="1 1 1 1"/>
      </material>
    </visual>
    <!-- Note: must omit name="foo" because in Gazebo 7 the urdf parser has a bug that would make <gazebo reference="bar"> not work -->
    <collision>
      <geometry>
        <cylinder length="0.4" radius="0.15"/>
      </geometry>
    </collision>
    <inertial>
      <mass value="0.15"/>
      <inertia ixx="0.00284375" ixy="0.0" ixz="0.0" iyy="0.00284375" iyz="0.0" izz="0.0016875"/>
    </inertial>
  </link>
  <!-- Camera link -->
  <link name="camera_link">
    <visual name="visual">
      <geometry>
        <box size="0.1 0.1 0.1"/>
      </geometry>
    </visual>
    <collision name="collision">
      <geometry>
        <box size="0.1 0.1 0.1"/>
      </geometry>
    </collision>
    <inertial>
      <mass value="0.1"/>
      <inertia ixx="0.000166666666667" ixy="0.0" ixz="0.0" iyy="0.000166666666667" iyz="0.0" izz="0.000166666666667"/>
    </inertial>
  </link>
  <!-- joints for attaching models to each other -->
  <!-- joint to attach UR10 to mobile base -->
  <joint name="arm_to_mobile_base" type="fixed">
    <origin rpy="0 0 0" xyz="0 0 0.176"/>
    <parent link="chassis"/>
    <child link="base_link"/>
  </joint>
  <!-- joint to attach mount for tool to UR10 -->
  <joint name="mount_to_ur10" type="fixed">
    <origin rpy="0 0 0" xyz="0 0 .005"/>
    <parent link="tool0"/>
    <child link="mount_link"/>
  </joint>
  <!-- joint to attach gripper to mount -->
  <joint name="gripper_to_mount" type="fixed">
    <origin rpy="0 0 0" xyz=".15 0 .205"/>
    <parent link="mount_link"/>
    <child link="gripper_link"/>
  </joint>
  <!-- joint to attach camera to mount -->
  <joint name="camera_to_mount" type="fixed">
    <origin rpy="0 0 0" xyz="-.15 0 .055"/>
    <parent link="mount_link"/>
    <child link="camera_link"/>
  </joint>
  <!-- temp attach mobile base to ground -->
  <!--link name="world" />
  <joint name="world_joint" type="fixed">
    <parent link="world" />
    <child link = "chassis" />
    <origin xyz="0.0 0.0 1.0" rpy="0.0 0.0 0.0" />
    </joint-->
</robot>

